Workbook

Sheet groupe
A1: 👥 EQUIPE PROJET — Cloud S5 RouteWatch
A2: NumETU | B2: Membre | C2: Rôle principal | D2: Note
A3: ETU0003525 | B3: Membre 1 | C3: Pilotage technique + architecture | D3: Travail solo
A4: ETU0003525 | B4: Membre 2 | C4: Backend API + base de donnees | D4: Travail solo
A5: ETU0003525 | B5: Membre 3 | C5: Web + carte offline | D5: Travail solo
A6: ETU0003525 | B6: Membre 4 | C6: Mobile + synchronisation | D6: Travail solo
A7: probleme pc plusieurs semaines

Sheet liste des taches
A1: 📋 LISTE DES TÂCHES — Cloud S5 RouteWatch | ETU0003525
A2: Ligne | B2: Version | C2: Catégorie | D2: Module | E2: Page/Service | F2: Description tâche | G2: Type | H2: Qui | I2: Estimation | J2: Estimation (h) | K2: Temps passé (h) | L2: Reste (h) | M2: Avancement | N2: Statut | O2: Priorité
A3: 1 | B3: V1 | C3: Cadrage | D3: Projet | E3: Global | F3: Lire le sujet et decouper en modules Auth/Carte/Web/Mobile/Livrables. | G3: Conception | H3: ETU0003525 | I3: 1 h 30 min | J3: 1.5 | K3: =3 -> 3 | L3: =-1.5 -> -1.5 | M3: =100% -> 1 | N3: Fait | O3: Haute
A4: 2 | B4: V1 | C4: Cadrage | D4: Architecture | E4: Docker | F4: Definir architecture cible multi-conteneurs et conventions de ports. | G4: Conception | H4: ETU0003525 | I4: 2 h | J4: 2 | K4: =detail_avancement!B3 -> 2 | L4: =J3-K3 -> -1.5 | M4: =IF(J3=0,0,K3/J3) -> 2 | N4: Fait | O4: Haute
A5: 3 | B5: V1 | C5: Base | D5: SQL | E5: script.sql | F5: Creer table roles (id, nom unique). | G5: Backend | H5: ETU0003525 | I5: 20 min | J5: 0.33 | K5: =detail_avancement!B4 -> 0.34 | L5: =J4-K4 -> 0 | M5: =IF(J4=0,0,K4/J4) -> 1 | N5: Fait | O5: Haute
A6: 4 | B6: V1 | C6: Base | D6: SQL | E6: script.sql | F6: Creer table utilisateurs (email, role, blocage, tentatives, dates). | G6: Backend | H6: ETU0003525 | I6: 45 min | J6: 0.75 | K6: =detail_avancement!B5 -> 0.76 | L6: =J5-K5 -> -0.01 | M6: =IF(J5=0,0,K5/J5) -> 1.030303 | N6: Fait | O6: Haute
A7: 5 | B7: V1 | C7: Base | D7: SQL | E7: script.sql | F7: Creer table sessions (token, expiration, actif). | G7: Backend | H7: ETU0003525 | I7: 30 min | J7: 0.5 | K7: =detail_avancement!B6 -> 0.5 | L7: =J6-K6 -> -0.01 | M7: =IF(J6=0,0,K6/J6) -> 1.0133333 | N7: Fait | O7: Haute
A8: 6 | B8: V1 | C8: Base | D8: SQL | E8: script.sql | F8: Creer table parametres_auth (limite_tentatives, duree_session). | G8: Backend | H8: ETU0003525 | I8: 25 min | J8: 0.42 | K8: =detail_avancement!B7 -> 0.42 | L8: =J7-K7 -> 0 | M8: =IF(J7=0,0,K7/J7) -> 1 | N8: Fait | O8: Haute
A9: 7 | B9: V1 | C9: Base | D9: Seed | E9: script.sql | F9: Inserer roles par defaut UTILISATEUR/MANAGER. | G9: Backend | H9: ETU0003525 | I9: 15 min | J9: 0.25 | K9: =detail_avancement!B8 -> 0.24 | L9: =J8-K8 -> 0 | M9: =IF(J8=0,0,K8/J8) -> 1 | N9: Fait | O9: Haute
A10: 8 | B10: V1 | C10: Base | D10: Seed | E10: script.sql | F10: Inserer manager par defaut admin@gmail.com. | G10: Backend | H10: ETU0003525 | I10: 20 min | J10: 0.33 | K10: =detail_avancement!B9 -> 0.34 | L10: =J9-K9 -> 0.01 | M10: =IF(J9=0,0,K9/J9) -> 0.96 | N10: Fait | O10: Haute
A11: 9 | B11: V1 | C11: Auth | D11: API | E11: /api/auth/register | F11: Implementer inscription locale PostgreSQL. | G11: Backend | H11: ETU0003525 | I11: 1 h | J11: 1 | K11: =detail_avancement!B10 -> 1 | L11: =J10-K10 -> -0.01 | M11: =IF(J10=0,0,K10/J10) -> 1.030303 | N11: Fait | O11: Haute
A12: 10 | B12: V1 | C12: Auth | D12: API | E12: /api/auth/login | F12: Implementer login email/mot de passe et retour token session. | G12: Backend | H12: ETU0003525 | I12: 1 h 30 min | J12: 1.5 | K12: =detail_avancement!B11 -> 1.5 | L12: =J11-K11 -> 0 | M12: =IF(J11=0,0,K11/J11) -> 1 | N12: Fait | O12: Haute
A13: 11 | B13: V1 | C13: Auth | D13: Securite | E13: Service auth | F13: Implementer duree de vie session configurable. | G13: Backend | H13: ETU0003525 | I13: 50 min | J13: 0.83 | K13: =detail_avancement!B12 -> 0.82 | L13: =J12-K12 -> 0 | M13: =IF(J12=0,0,K12/J12) -> 1 | N13: Fait | O13: Haute
A14: 12 | B14: V1 | C14: Auth | D14: Securite | E14: Service auth | F14: Implementer limite tentatives (defaut 3) + blocage compte. | G14: Backend | H14: ETU0003525 | I14: 1 h | J14: 1 | K14: =detail_avancement!B13 -> 1 | L14: =J13-K13 -> 0.01 | M14: =IF(J13=0,0,K13/J13) -> 0.98795181 | N14: Fait | O14: Haute
A15: 13 | B15: V1 | C15: Auth | D15: API | E15: /api/auth/reset-lock/{id} | F15: Implementer API REST de deblocage utilisateur. | G15: Backend | H15: ETU0003525 | I15: 40 min | J15: 0.67 | K15: =detail_avancement!B14 -> 0.68 | L15: =J14-K14 -> 0 | M15: =IF(J14=0,0,K14/J14) -> 1 | N15: Fait | O15: Haute
... A39: 37 | B39: V3 | C39: Mobile | D39: Build | E39: Android | F39: Corriger erreur VANILLA_ICE_CREAM (SDK/Java/Capacitor). | G39: Mobile | H39: ETU0003525 | I39: 1 h | J39: 1 | K39: =detail_avancement!B38 -> 1 | L39: =J38-K38 -> 0.01 | M39: =IF(J38=0,0,K38/J38) -> 0.992 | N39: Fait | O39: Haute
A40: 38 | B40: V3 | C40: Mobile | D40: Build | E40: APK | F40: Assembler APK debug et verifier installation. | G40: Mobile | H40: ETU0003525 | I40: 30 min | J40: 0.5 | K40: =2 -> 2 | L40: =J39-K39 -> 0 | M40: =IF(J39=0,0,K39/J39) -> 1 | N40: Fait | O40: Haute
A41: 39 | B41: V3 | C41: Web | D41: UI Map | E41: Dashboard | F41: Optimiser zoom, centre, lisibilite labels et densite contenu. | G41: Frontend | H41: ETU0003525 | I41: 1 h | J41: 1 | K41: =detail_avancement!B40 -> 1 | L41: =J40-K40 -> -1.5 | M41: =IF(J40=0,0,K40/J40) -> 4 | N41: Fait | O41: Haute
A42: 40 | B42: V3 | C42: Web | D42: UI Map | E42: Dashboard | F42: Ameliorer icones signalements par type de probleme. | G42: Frontend | H42: ETU0003525 | I42: 45 min | J42: 0.75 | K42: =detail_avancement!B41 -> 0.76 | L42: =J41-K41 -> 0 | M42: =IF(J41=0,0,K41/J41) -> 1 | N42: Fait | O42: Haute
A43: 41 | B43: V4 | C43: Base | D43: Auto-init | E43: application-docker.properties | F43: Forcer execution auto script.sql au demarrage conteneur. | G43: Backend | H43: ETU0003525 | I43: 35 min | J43: 0.58 | K43: =detail_avancement!B42 -> 0.58 | L43: =J42-K42 -> -0.01 | M43: =IF(J42=0,0,K42/J42) -> 1.0133333 | N43: Fait | O43: Haute
A44: 42 | B44: V4 | C44: Base | D44: script.sql | E44: route/resources | F44: Rendre script idempotent (CREATE IF NOT EXISTS + INSERT guarded). | G44: Backend | H44: ETU0003525 | I44: 1 h 10 min | J44: 1.17 | K44: =detail_avancement!B43 -> 1.16 | L44: =J43-K43 -> 0 | M44: =IF(J43=0,0,K43/J43) -> 1 | N44: Fait | O44: Haute
A45: 43 | B45: V4 | C45: Base | D45: Seed | E45: script.sql | F45: Injecter donnees tests coherentes (lieux, signalements, travaux). | G45: Backend | H45: ETU0003525 | I45: 1 h | J45: 1 | K45: =detail_avancement!B44 -> 1 | L45: =J44-K44 -> 0.01 | M45: =IF(J44=0,0,K44/J44) -> 0.99145299 | N45: Fait | O45: Haute
A46: 44 | B46: V4 | C46: Web | D46: Robustesse | E46: Parsing | F46: Normaliser statuts et nombres pour coherence web/mobile. | G46: Frontend | H46: ETU0003525 | I46: 50 min | J46: 0.83 | K46: =detail_avancement!B45 -> 0.82 | L46: =J45-K45 -> 0 | M46: =IF(J45=0,0,K45/J45) -> 1 | N46: Fait | O46: Haute
A47: 45 | B47: V4 | C47: Backend | D47: Travaux | E47: /api/travaux/stats/delais | F47: Ajouter stats delais min/moy/max. | G47: Backend | H47: ETU0003525 | I47: 55 min | J47: 0.92 | K47: =detail_avancement!B46 -> 0.92 | L47: =J46-K46 -> 0.01 | M47: =IF(J46=0,0,K46/J46) -> 0.98795181 | N47: Fait | O47: Haute
A48: 46 | B48: V4 | C48: Security | D48: Auth | E48: Sessions | F48: Invalidation sessions lors de deblocage/operations critiques. | G48: Backend | H48: ETU0003525 | I48: 40 min | J48: 0.67 | K48: =detail_avancement!B47 -> 0.68 | L48: =J47-K47 -> 0 | M48: =IF(J47=0,0,K47/J47) -> 1 | N48: Fait | O48: Haute
A49: 47 | B49: V4 | C49: QA | D49: Tests | E49: Postman | F49: Verifier flux complet auth + signalement + travaux + sync. | G49: QA | H49: ETU0003525 | I49: 1 h | J49: 1 | K49: =2 -> 2 | L49: =J48-K48 -> -0.01 | M49: =IF(J48=0,0,K48/J48) -> 1.0149254 | N49: Fait | O49: Haute
A50: 48 | B50: V4 | C50: Doc | D50: Execution | E50: README | F50: Mettre guide lancement docker et builds. | G50: Doc | H50: ETU0003525 | I50: 45 min | J50: 0.75 | K50: =detail_avancement!B49 -> 0.76 | L50: =J49-K49 -> -1 | M50: =IF(J49=0,0,K49/J49) -> 2 | N50: Fait | O50: Haute
A51: 49 | B51: V5 | C51: Pro | D51: Analytics | E51: /api/analytics/criticality | F51: Scoring criticite multi-facteurs pour prioriser interventions. | G51: Backend | H51: ETU0003525 | I51: 1 h 20 min | J51: 1.33 | K51: =detail_avancement!B50 -> 1.33 | L51: =J50-K50 -> -0.01 | M51: =IF(J50=0,0,K50/J50) -> 1.0133333 | N51: Fait | O51: Critique
A52: 50 | B52: V5 | C52: Pro | D52: Audit | E52: /api/analytics/audit | F52: Table audit_logs + journal actions create/update/delete/lock/unlock. | G52: Backend | H52: ETU0003525 | I52: 1 h 20 min | J52: 1.33 | K52: =detail_avancement!B51 -> 1.33 | L52: =J51-K51 -> 0 | M52: =IF(J51=0,0,K51/J51) -> 1 | N52: Fait | O52: Critique
A53: 51 | B53: V5 | C53: Pro | D53: Analytics | E53: /api/analytics/impact | F53: KPI impact: ouverts/clotures, budget/m2, delai moyen, hotspots. | G53: Backend | H53: ETU0003525 | I53: 1 h | J53: 1 | K53: =1.3 -> 1.3 | L53: =J52-K52 -> 0 | M53: =IF(J52=0,0,K52/J52) -> 1 | N53: Fait | O53: Critique
A54: 52 | B54: V5 | C54: Pro | D54: Web | E54: /analytics/criticality | F54: Page web Criticite dediee. | G54: Frontend | H54: ETU0003525 | I54: 50 min | J54: 0.83 | K54: =detail_avancement!B53 -> 0.83 | L54: =J53-K53 -> -0.3 | M54: =IF(J53=0,0,K53/J53) -> 1.3 | N54: Fait | O54: Haute
A55: 53 | B55: V5 | C55: Pro | D55: Web | E55: /analytics/audit | F55: Page web Audit Trail dediee. | G55: Frontend | H55: ETU0003525 | I55: 45 min | J55: 0.75 | K55: =detail_avancement!B54 -> 0.75 | L55: =J54-K54 -> 0 | M55: =IF(J54=0,0,K54/J54) -> 1 | N55: Fait | O55: Haute
A56: 54 | B56: V5 | C56: Pro | D56: Web | E56: /analytics/impact | F56: Page web Impact & performance dediee. | G56: Frontend | H56: ETU0003525 | I56: 45 min | J56: 0.75 | K56: =detail_avancement!B55 -> 0.75 | L56: =J55-K55 -> 0 | M56: =IF(J55=0,0,K55/J55) -> 1 | N56: Fait | O56: Haute
A57: 55 | B57: V5 | C57: Pro | D57: Web | E57: Widget | F57: Mini carte scrollable utilisateurs bloques en bas droite. | G57: Frontend | H57: ETU0003525 | I57: 35 min | J57: 0.58 | K57: =detail_avancement!B56 -> 0.58 | L57: =J56-K56 -> 0 | M57: =IF(J56=0,0,K56/J56) -> 1 | N57: Fait | O57: Haute
A58: 56 | B58: V5 | C58: Pro | D58: Mobile | E58: Tab2 | F58: 3 contenus mobiles synchronises: Criticite, Audit, Impact. | G58: Mobile | H58: ETU0003525 | I58: 1 h 30 min | J58: 1.5 | K58: =detail_avancement!B57 -> 1.5 | L58: =J57-K57 -> 0 | M58: =IF(J57=0,0,K57/J57) -> 1 | N58: Fait | O58: Critique
A59: 57 | B59: V5 | C59: Pro | D59: Base | E59: script.sql | F59: Seed utilisateur bloque + jeux de donnees analytics. | G59: Backend | H59: ETU0003525 | I59: 40 min | J59: 0.67 | K59: =detail_avancement!B58 -> 0.67 | L59: =J58-K58 -> 0 | M59: =IF(J58=0,0,K58/J58) -> 1 | N59: Fait | O59: Haute
A60: 58 | B60: V5 | C60: Pro | D60: Verification | E60: Builds | F60: Valider compilation Maven + build web + build mobile. | G60: QA | H60: ETU0003525 | I60: 30 min | J60: 0.5 | K60: =detail_avancement!B59 -> 0.5 | L60: =J59-K59 -> 0 | M60: =IF(J59=0,0,K59/J59) -> 1 | N60: Fait | O60: Haute
A61: 59 | B61: V5 | C61: Pro | D61: Analytics | E61: /analytics | F61: Corriger page /analytics/audit vide: initialisation automatique du journal (seed SQL + fallback backend). | G61: Backend | H61: ETU0003525 | I61: 35 min | J61: 0.58 | K61: =detail_avancement!B60 -> 0.58 | L61: =J60-K60 -> 0 | M61: =IF(J60=0,0,K60/J60) -> 1 | N61: Fait | O61: Critique
A62: 60 | B62: V5 | C62: Pro | D62: Analytics | E62: /analytics | F62: Ajouter nouvelle page /analytics/charts avec graphiques globaux (statuts, types, criticite) et navigation. | G62: Frontend | H62: ETU0003525 | I62: 4 h 15 min | J62: 4.25 | K62: =6 -> 6 | L62: =J61-K61 -> 0 | M62: =IF(J61=0,0,K61/J61) -> 1 | N62: Fait | O62: Haute
A63: 61 | C63: pro | D63: projet | E63: dossier du projet | F63: restructuration du projet selon le livrable(crypto….) | G63: terminal | H63: ETU003525 | I63: 30min
...

Sheet detail_avancement
A1: Ligne | B1: Total | C1: 46035 | D1: 46036 | E1: 46037 | F1: 46038 | G1: 46039 | H1: 46040 | I1: 46041 | J1: 46042 | K1: 46043 | L1: 46044 | M1: 46045 | N1: 46046 | O1: 46047 | P1: 46048 | Q1: 46049 | R1: 46050 | S1: 46051 | T1: 46052 | U1: 46053 | V1: 46054 | W1: 46055 | X1: 46056 | Y1: 46057 | Z1: 46058 | AA1: 46059 | AB1: 46060 | AC1: 46061 | AD1: 46062 | AE1: 46063 | AF1: 46064 | AG1: 46065 | AH1: 46066 | AI1: 46067 | AJ1: 46068 | AK1: 46071
A2: 1 | B2: =SUM(C2:AJ2) -> 1.5 | C2: 0.75 | D2: 0.75 | E2: 0 | F2: 0 | G2: 0 | H2: 0 | I2: 0 | J2: 0 | K2: 0 | L2: 0 | M2: 0 | N2: 0 | O2: 0 | P2: 0 | Q2: 0 | R2: 0 | S2: 0 | T2: 0 | U2: 0 | V2: 0 | W2: 0 | X2: 0 | Y2: 0 | Z2: 0 | AA2: 0 | AB2: 0 | AC2: 0 | AD2: 0 | AE2: 0 | AF2: 0 | AG2: 0 | AH2: 0 | AI2: 0 | AJ2: 0
A3: 2 | B3: =SUM(C3:AJ3) -> 2 | C3: 1 | D3: 1 | E3: 0 | F3: 0 | G3: 0 | H3: 0 | I3: 0 | J3: 0 | K3: 0 | L3: 0 | M3: 0 | N3: 0 | O3: 0 | P3: 0 | Q3: 0 | R3: 0 | S3: 0 | T3: 0 | U3: 0 | V3: 0 | W3: 0 | X3: 0 | Y3: 0 | Z3: 0 | AA3: 0 | AB3: 0 | AC3: 0 | AD3: 0 | AE3: 0 | AF3: 0 | AG3: 0 | AH3: 0 | AI3: 0 | AJ3: 0
A4: 3 | B4: =SUM(C4:AJ4) -> 0.34 | C4: 0.17 | D4: 0.17 | E4: 0 | F4: 0 | G4: 0 | H4: 0 | I4: 0 | J4: 0 | K4: 0 | L4: 0 | M4: 0 | N4: 0 | O4: 0 | P4: 0 | Q4: 0 | R4: 0 | S4: 0 | T4: 0 | U4: 0 | V4: 0 | W4: 0 | X4: 0 | Y4: 0 | Z4: 0 | AA4: 0 | AB4: 0 | AC4: 0 | AD4: 0 | AE4: 0 | AF4: 0 | AG4: 0 | AH4: 0 | AI4: 0 | AJ4: 0
A5: 4 | B5: =SUM(C5:AJ5) -> 0.76 | C5: 0.38 | D5: 0.38 | E5: 0 | F5: 0 | G5: 0 | H5: 0 | I5: 0 | J5: 0 | K5: 0 | L5: 0 | M5: 0 | N5: 0 | O5: 0 | P5: 0 | Q5: 0 | R5: 0 | S5: 0 | T5: 0 | U5: 0 | V5: 0 | W5: 0 | X5: 0 | Y5: 0 | Z5: 0 | AA5: 0 | AB5: 0 | AC5: 0 | AD5: 0 | AE5: 0 | AF5: 0 | AG5: 0 | AH5: 0 | AI5: 0 | AJ5: 0
A6: 5 | B6: =SUM(C6:AJ6) -> 0.5 | C6: 0.25 | D6: 0.25 | E6: 0 | F6: 0 | G6: 0 | H6: 0 | I6: 0 | J6: 0 | K6: 0 | L6: 0 | M6: 0 | N6: 0 | O6: 0 | P6: 0 | Q6: 0 | R6: 0 | S6: 0 | T6: 0 | U6: 0 | V6: 0 | W6: 0 | X6: 0 | Y6: 0 | Z6: 0 | AA6: 0 | AB6: 0 | AC6: 0 | AD6: 0 | AE6: 0 | AF6: 0 | AG6: 0 | AH6: 0 | AI6: 0 | AJ6: 0
A7: 6 | B7: =SUM(C7:AJ7) -> 0.42 | C7: 0.21 | D7: 0.21 | E7: 0 | F7: 0 | G7: 0 | H7: 0 | I7: 0 | J7: 0 | K7: 0 | L7: 0 | M7: 0 | N7: 0 | O7: 0 | P7: 0 | Q7: 0 | R7: 0 | S7: 0 | T7: 0 | U7: 0 | V7: 0 | W7: 0 | X7: 0 | Y7: 0 | Z7: 0 | AA7: 0 | AB7: 0 | AC7: 0 | AD7: 0 | AE7: 0 | AF7: 0 | AG7: 0 | AH7: 0 | AI7: 0 | AJ7: 0
A8: 7 | B8: =SUM(C8:AJ8) -> 0.24 | C8: 0.12 | D8: 0.12 | E8: 0 | F8: 0 | G8: 0 | H8: 0 | I8: 0 | J8: 0 | K8: 0 | L8: 0 | M8: 0 | N8: 0 | O8: 0 | P8: 0 | Q8: 0 | R8: 0 | S8: 0 | T8: 0 | U8: 0 | V8: 0 | W8: 0 | X8: 0 | Y8: 0 | Z8: 0 | AA8: 0 | AB8: 0 | AC8: 0 | AD8: 0 | AE8: 0 | AF8: 0 | AG8: 0 | AH8: 0 | AI8: 0 | AJ8: 0
A9: 8 | B9: =SUM(C9:AJ9) -> 0.34 | C9: 0.17 | D9: 0.17 | E9: 0 | F9: 0 | G9: 0 | H9: 0 | I9: 0 | J9: 0 | K9: 0 | L9: 0 | M9: 0 | N9: 0 | O9: 0 | P9: 0 | Q9: 0 | R9: 0 | S9: 0 | T9: 0 | U9: 0 | V9: 0 | W9: 0 | X9: 0 | Y9: 0 | Z9: 0 | AA9: 0 | AB9: 0 | AC9: 0 | AD9: 0 | AE9: 0 | AF9: 0 | AG9: 0 | AH9: 0 | AI9: 0 | AJ9: 0
A10: 9 | B10: =SUM(C10:AJ10) -> 1 | C10: 0.5 | D10: 0.5 | E10: 0 | F10: 0 | G10: 0 | H10: 0 | I10: 0 | J10: 0 | K10: 0 | L10: 0 | M10: 0 | N10: 0 | O10: 0 | P10: 0 | Q10: 0 | R10: 0 | S10: 0 | T10: 0 | U10: 0 | V10: 0 | W10: 0 | X10: 0 | Y10: 0 | Z10: 0 | AA10: 0 | AB10: 0 | AC10: 0 | AD10: 0 | AE10: 0 | AF10: 0 | AG10: 0 | AH10: 0 | AI10: 0 | AJ10: 0
A11: 10 | B11: =SUM(C11:AJ11) -> 1.5 | C11: 0.75 | D11: 0.75 | E11: 0 | F11: 0 | G11: 0 | H11: 0 | I11: 0 | J11: 0 | K11: 0 | L11: 0 | M11: 0 | N11: 0 | O11: 0 | P11: 0 | Q11: 0 | R11: 0 | S11: 0 | T11: 0 | U11: 0 | V11: 0 | W11: 0 | X11: 0 | Y11: 0 | Z11: 0 | AA11: 0 | AB11: 0 | AC11: 0 | AD11: 0 | AE11: 0 | AF11: 0 | AG11: 0 | AH11: 0 | AI11: 0 | AJ11: 0
A12: 11 | B12: =SUM(C12:AJ12) -> 0.82 | C12: 0.41 | D12: 0.41 | E12: 0 | F12: 0 | G12: 0 | H12: 0 | I12: 0 | J12: 0 | K12: 0 | L12: 0 | M12: 0 | N12: 0 | O12: 0 | P12: 0 | Q12: 0 | R12: 0 | S12: 0 | T12: 0 | U12: 0 | V12: 0 | W12: 0 | X12: 0 | Y12: 0 | Z12: 0 | AA12: 0 | AB12: 0 | AC12: 0 | AD12: 0 | AE12: 0 | AF12: 0 | AG12: 0 | AH12: 0 | AI12: 0 | AJ12: 0
A13: 12 | B13: =SUM(C13:AJ13) -> 1 | C13: 0.5 | D13: 0.5 | E13: 0 | F13: 0 | G13: 0 | H13: 0 | I13: 0 | J13: 0 | K13: 0 | L13: 0 | M13: 0 | N13: 0 | O13: 0 | P13: 0 | Q13: 0 | R13: 0 | S13: 0 | T13: 0 | U13: 0 | V13: 0 | W13: 0 | X13: 0 | Y13: 0 | Z13: 0 | AA13: 0 | AB13: 0 | AC13: 0 | AD13: 0 | AE13: 0 | AF13: 0 | AG13: 0 | AH13: 0 | AI13: 0 | AJ13: 0
... A59: 58 | B59: =SUM(C59:AJ59) -> 0.5 | C59: 0 | D59: 0 | E59: 0 | F59: 0 | G59: 0 | H59: 0 | I59: 0 | J59: 0 | K59: 0 | L59: 0 | M59: 0 | N59: 0 | O59: 0 | P59: 0 | Q59: 0 | R59: 0 | S59: 0 | T59: 0 | U59: 0 | V59: 0 | W59: 0 | X59: 0 | Y59: 0 | Z59: 0 | AA59: 0 | AB59: 0 | AC59: 0 | AD59: 0 | AE59: 0 | AF59: 0 | AG59: 0 | AH59: 0 | AI59: 0 | AJ59: 0.5
A60: 59 | B60: =SUM(C60:AJ60) -> 0.58 | C60: 0.58
A61: 60 | B61: =SUM(C61:AJ61) -> 1.25 | C61: 1.25
A62: 63 | B62: 0.75 | AK62: 0.75
A63: 64 | B63: 0.67 | AK63: 0.67
A64: 65 | B64: 1 | AK64: 1
A65: 66 | B65: 0.83 | AK65: 0.83
A66: 67 | B66: 0.67 | AK66: 0.67
A67: 68 | B67: 1 | AK67: 1
A68: 69 | B68: 0.75 | AK68: 0.75
A69: 70 | B69: 1.33 | AK69: 1.33
A70: 71 | B70: 0.83 | AK70: 0.83
A71: 72 | B71: 0.58 | AK71: 0.58
A72: 73 | B72: 0.5 | AK72: 0.5
A73: 74 | B73: 0.83 | AK73: 0.83
... A76: 77 | B76: 0.58 | AK76: 0.58

Sheet avancement
A1: 📊 AVANCEMENT GLOBAL — Cloud S5 RouteWatch
A3: Estimation totale (h) | B3: Temps passé total (h) | C3: Reste total (h) | D3: Avancement global | E3: Dépassement | F3: Reste en jours (8h)
A4: =SUM('liste des taches'!J:J) -> 79.97 | B4: =SUM('liste des taches'!K:K) -> 93.37 | C4: =SUM('liste des taches'!L:L) -> -5.82 | D4: =IF(A4=0,0,B4/A4) -> 1.1675628 | E4: =IF(A4=0,0,(B4-A4)/A4) -> 0.16756284 | F4: =IF(C4=0,0,C4/8) -> -0.7275 | G4: probleme pc plusieurs semaines
A6: 📋 Détail par version
A7: Version | B7: Nb tâches | C7: Estimation (h) | D7: Temps passé (h) | E7: Avancement | F7: Statut
A8: V1 | B8: =COUNTIF('liste des taches'!B:B,"V1") -> 15 | C8: =SUMIFS('liste des taches'!J:J,'liste des taches'!B:B,"V1") -> 12.66 | D8: =SUMIFS('liste des taches'!K:K,'liste des taches'!B:B,"V1") -> 14.18 | E8: =IF(C8=0,0,D8/C8) -> 1.1200632 | F8: =IF(E8>=1,"✅ Fait",IF(E8>0,"🔄 En cours","⏳ À faire")) -> ✅ Fait
A9: V2 | B9: =COUNTIF('liste des taches'!B:B,"V2") -> 15 | C9: =SUMIFS('liste des taches'!J:J,'liste des taches'!B:B,"V2") -> 19.42 | D9: =SUMIFS('liste des taches'!K:K,'liste des taches'!B:B,"V2") -> 19.42 | E9: =IF(C9=0,0,D9/C9) -> 1 | F9: =IF(E9>=1,"✅ Fait",IF(E9>0,"🔄 En cours","⏳ À faire")) -> ✅ Fait
A10: V3 | B10: =COUNTIF('liste des taches'!B:B,"V3") -> 19 | C10: =SUMIFS('liste des taches'!J:J,'liste des taches'!B:B,"V3") -> 21.98 | D10: =SUMIFS('liste des taches'!K:K,'liste des taches'!B:B,"V3") -> 26.48 | E10: =IF(C10=0,0,D10/C10) -> 1.2047316 | F10: =IF(E10>=1,"✅ Fait",IF(E10>0,"🔄 En cours","⏳ À faire")) -> ✅ Fait
A11: V4 | B11: =COUNTIF('liste des taches'!B:B,"V4") -> 14 | C11: =SUMIFS('liste des taches'!J:J,'liste des taches'!B:B,"V4") -> 11.84 | D11: =SUMIFS('liste des taches'!K:K,'liste des taches'!B:B,"V4") -> 17.17 | E11: =IF(C11=0,0,D11/C11) -> 1.4501689 | F11: =IF(E11>=1,"✅ Fait",IF(E11>0,"🔄 En cours","⏳ À faire")) -> ✅ Fait
A12: V5 | B12: =COUNTIF('liste des taches'!B:B,"V5") -> 12 | C12: =SUMIFS('liste des taches'!J:J,'liste des taches'!B:B,"V5") -> 14.07 | D12: =SUMIFS('liste des taches'!K:K,'liste des taches'!B:B,"V5") -> 16.12 | E12: =IF(C12=0,0,D12/C12) -> 1.1457001 | F12: =IF(E12>=1,"✅ Fait",IF(E12>0,"🔄 En cours","⏳ À faire")) -> ✅ Fait
A13: 🔥 Firebase | B13: 15 tâches Firebase intégrées dans V3 (Web+Mobile) et V4 (Backend) — 18/02/2026

Sheet Recap
A1: 📌 RÉCAPITULATIF PROJET — Cloud S5 RouteWatch
A2: Projet | B2: Cloud S5 - RouteWatch
A3: Promotion | B3: 17
A4: NumETU | B4: ETU0003525
A5: Versions | B5: V1 13/01/2026 | V2 20/01/2026 | V3 03/02/2026 | V4 10/02/2026 | V5 15/02/2026 | Firebase 18/02/2026 (dans V3/V4)
A6: Total taches | B6: =COUNTA('liste des taches'!A:A)-1 -> 78
A7: Estimation totale (h) | B7: =avancement!A2 -> 0
A8: Temps passe total (h) | B8: =avancement!B2 -> 0
A9: Reste total (h) | B9: =avancement!C2 -> 0
A10: Avancement global | B10: =avancement!D2 -> 0
A11: Commentaire | B11: Ordre aligne au sujet + V5 analytics/audit/impact; mobile login via Firebase Auth + sync backend local.
A13: Livrable | B13: Statut
A14: Sources | B14: Fait
A15: Docker compose | B15: Fait
A16: Collection Postman | B16: Fait
A17: APK | B17: Fait
A18: Documentation technique | B18: En cours

Sheet V1
A1: 🚀 V1 —
A2: Version | B2: V1
A3: Date | B3: 13/01/2026
A4: Objectif | B4: Auth API + base locale + Swagger
A6: Ligne | B6: Categorie | C6: Module | D6: Page/Service | E6: Description | F6: Type | G6: Qui | H6: Estimation | I6: Statut | J6: Priorite
A7: 1 | B7: Cadrage | C7: Projet | D7: Global | E7: Lire le sujet et decouper en modules Auth/Carte/Web/Mobile/Livrables. | F7: Conception | G7: ETU0003525 | H7: 1 h 30 min | I7: Fait | J7: Haute
A8: 2 | B8: Cadrage | C8: Architecture | D8: Docker | E8: Definir architecture cible multi-conteneurs et conventions de ports. | F8: Conception | G8: ETU0003525 | H8: 2 h | I8: Fait | J8: Haute
A9: 3 | B9: Base | C9: SQL | D9: script.sql | E9: Creer table roles (id, nom unique). | F9: Backend | G9: ETU0003525 | H9: 20 min | I9: Fait | J9: Haute
A10: 4 | B10: Base | C10: SQL | D10: script.sql | E10: Creer table utilisateurs (email, role, blocage, tentatives, dates). | F10: Backend | G10: ETU0003525 | H10: 45 min | I10: Fait | J10: Haute
A11: 5 | B11: Base | C11: SQL | D11: script.sql | E11: Creer table sessions (token, expiration, actif). | F11: Backend | G11: ETU0003525 | H11: 30 min | I11: Fait | J11: Haute
A12: 6 | B12: Base | C12: SQL | D12: script.sql | E12: Creer table parametres_auth (limite_tentatives, duree_session). | F12: Backend | G12: ETU0003525 | H12: 25 min | I12: Fait | J12: Haute
A13: 7 | B13: Base | C13: Seed | D13: script.sql | E13: Inserer roles par defaut UTILISATEUR/MANAGER. | F13: Backend | G13: ETU0003525 | H13: 15 min | I13: Fait | J13: Haute
A14: 8 | B14: Base | C14: Seed | D14: script.sql | E14: Inserer manager par defaut admin@gmail.com. | F14: Backend | G14: ETU0003525 | H14: 20 min | I14: Fait | J14: Haute
A15: 9 | B15: Auth | C15: API | D15: /api/auth/register | E15: Implementer inscription locale PostgreSQL. | F15: Backend | G15: ETU0003525 | H15: 1 h | I15: Fait | J15: Haute
A16: 10 | B16: Auth | C16: API | D16: /api/auth/login | E16: Implementer login email/mot de passe et retour token session. | F16: Backend | G16: ETU0003525 | H16: 1 h 30 min | I16: Fait | J16: Haute
A17: 11 | B17: Auth | C17: Securite | D17: Service auth | E17: Implementer duree de vie session configurable. | F17: Backend | G17: ETU0003525 | H17: 50 min | I17: Fait | J17: Haute
A18: 12 | B18: Auth | C18: Securite | D18: Service auth | E18: Implementer limite tentatives (defaut 3) + blocage compte. | F18: Backend | G18: ETU0003525 | H18: 1 h | I18: Fait | J18: Haute
... A21: 15 | B21: Doc | C21: Swagger | D21: OpenAPI | E21: Exposer et verifier documentation API Auth. | F21: Backend | G21: ETU0003525 | H21: 35 min | I21: Fait | J21: Haute

Sheet V2
A1: 🚀 V2 —
A2: Version | B2: V2
A3: Date | B3: 20/01/2026
A4: Objectif | B4: Carte offline + web visiteur/manager
A6: Ligne | B6: Categorie | C6: Module | D6: Page/Service | E6: Description | F6: Type | G6: Qui | H6: Estimation | I6: Statut | J6: Priorite
A7: 1 | B7: Carte | C7: Serveur offline | D7: CARTE | E7: Configurer serveur carte offline dans Docker (MBTiles Antananarivo). | F7: DevOps | G7: ETU0003525 | H7: 2 h | I7: Fait | J7: Haute
A8: 2 | B8: Carte | C8: Tuiles | D8: server.js | E8: Servir tuiles vectorielles et style local sans internet. | F8: Backend | G8: ETU0003525 | H8: 1 h 20 min | I8: Fait | J8: Haute
A9: 3 | B9: Carte | C9: Style | D9: style.json | E9: Ajuster style pour rues, eau, zones urbaines. | F9: Frontend | G9: ETU0003525 | H9: 1 h | I9: Fait | J9: Haute
A10: 4 | B10: Carte | C10: Qualite | D10: Routing static | E10: Corriger routes /styles/data et /data pour supprimer 404/blank map. | F10: Backend | G10: ETU0003525 | H10: 1 h | I10: Fait | J10: Haute
A11: 5 | B11: Web | C11: Visiteur | D11: /visiteur | E11: Afficher carte et points de problemes routiers. | F11: Frontend | G11: ETU0003525 | H11: 1 h 30 min | I11: Fait | J11: Haute
A12: 6 | B12: Web | C12: Visiteur | D12: Popup | E12: Afficher date, statut, surface, budget, entreprise, photos, niveau. | F12: Frontend | G12: ETU0003525 | H12: 2 h | I12: Fait | J12: Haute
A13: 7 | B13: Web | C13: Visiteur | D13: Recap | E13: Afficher nb points, surface totale, avancement moyen, budget total. | F13: Frontend | G13: ETU0003525 | H13: 1 h 10 min | I13: Fait | J13: Haute
A14: 8 | B14: Web | C14: Manager | D14: / | E14: Connexion manager via API Auth. | F14: Frontend | G14: ETU0003525 | H14: 1 h | I14: Fait | J14: Haute
A15: 9 | B15: Web | C15: Manager | D15: Comptes | E15: Creer/editer/supprimer comptes utilisateurs. | F15: Frontend | G15: ETU0003525 | H15: 1 h 40 min | I15: Fait | J15: Haute
A16: 10 | B16: Web | C16: Manager | D16: Blocage | E16: Page de deblocage des utilisateurs bloques. | F16: Frontend | G16: ETU0003525 | H16: 50 min | I16: Fait | J16: Haute
A17: 11 | B17: Web | C17: Manager | D17: Signalements | E17: Saisir/editer surface, budget, entreprise, statut. | F17: Frontend | G17: ETU0003525 | H17: 2 h | I17: Fait | J17: Haute
A18: 12 | B18: Web | C18: Manager | D18: Calcul | E18: Calcul budget auto = prix_par_m2 * niveau * surface_m2. | F18: Frontend | G18: ETU0003525 | H18: 45 min | I18: Fait | J18: Haute
... A21: 15 | B21: Sync | C21: Firebase/local | D21: Bouton sync | E21: Ajouter synchronisation pull/push des donnees. | F21: Backend | G21: ETU0003525 | H21: 1 h 30 min | I21: Fait | J21: Haute

Sheet V3
A1: 🚀 V3 — Mobile synchronisé + Firebase Web/Mobile + APK
A2: Version | B2: V3
A3: Date | B3: 03/02/2026
A4: Objectif | B4: Mobile synchronise + notifications + APK
A6: Ligne | B6: Categorie | C6: Module | D6: Page/Service | E6: Description | F6: Type | G6: Qui | H6: Estimation | I6: Statut | J6: Priorite
A7: 1 | B7: Mobile | C7: Login | D7: Tab1 | E7: Connecter mobile a Firebase Auth (email/password), verifier blocage via backend et synchroniser utilisateur local (/api/auth/mobile-login). | F7: Mobile | G7: ETU0003525 | H7: 1 h 20 min | I7: Fait | J7: Haute
A8: 2 | B8: Mobile | C8: Carte | D8: Tab2 | E8: Afficher carte + geolocalisation + clic pour nouveau signalement. | F8: Mobile | G8: ETU0003525 | H8: 2 h | I8: Fait | J8: Haute
A9: 3 | B9: Mobile | C9: Signalement | D9: Tab2 | E9: Ajouter type, surface, description, multi-photos. | F9: Mobile | G9: ETU0003525 | H9: 1 h 30 min | I9: Fait | J9: Haute
A10: 4 | B10: Mobile | C10: Filtre | D10: Tab2 | E10: Filtre 'mes signalements uniquement'. | F10: Mobile | G10: ETU0003525 | H10: 35 min | I10: Fait | J10: Haute
A11: 5 | B11: Mobile | C11: Recap | D11: Tab2 | E11: Afficher recap mobile identique au visiteur web. | F11: Mobile | G11: ETU0003525 | H11: 50 min | I11: Fait | J11: Haute
A12: 6 | B12: Mobile | C12: Notifications | D12: Tab3 | E12: Notifier changement statut de mes signalements. | F12: Mobile | G12: ETU0003525 | H12: 1 h 15 min | I12: Fait | J12: Haute
A13: 7 | B13: Mobile | C13: Build | D13: Android | E13: Corriger erreur VANILLA_ICE_CREAM (SDK/Java/Capacitor). | F13: Mobile | G13: ETU0003525 | H13: 1 h | I13: Fait | J13: Haute
A14: 8 | B14: Mobile | C14: Build | D14: APK | E14: Assembler APK debug et verifier installation. | F14: Mobile | G14: ETU0003525 | H14: 30 min | I14: Fait | J14: Haute
A15: 9 | B15: Web | C15: UI Map | D15: Dashboard | E15: Optimiser zoom, centre, lisibilite labels et densite contenu. | F15: Frontend | G15: ETU0003525 | H15: 1 h | I15: Fait | J15: Haute
A16: 10 | B16: Web | C16: UI Map | D16: Dashboard | E16: Ameliorer icones signalements par type de probleme. | F16: Frontend | G16: ETU0003525 | H16: 45 min | I16: Fait | J16: Haute
A17: 🔥 Firebase — Intégration Web & Mobile (18/02/2026)
A18: 12 | B18: Firebase | C18: Web | D18: firebase.ts (front-crypto) | E18: Init app Firebase cloud-mobile-c6ab2 + auth + Firestore + persistance IndexedDB offline + isFirebaseInitialized() + testFirebaseConnection() | F18: Frontend | G18: ETU0003525 | H18: 45 min | I18: Fait | J18: Haute
A19: 13 | B19: Firebase | C19: Web | D19: firebaseSyncService.ts (Web) | E19: CRUD Firestore: addSignalement/updateSignalement/deleteSignalement + addTravaux/updateTravaux + addUtilisateur/updateUtilisateur | F19: Frontend | G19: ETU0003525 | H19: 1 h 20 min | I19: Fait | J19: Haute
A20: 14 | B20: Firebase | C20: Web | D20: firebaseSyncService.ts (Web) | E20: Temps reel onSnapshot: subscribeToSignalements() + subscribeToTravaux() + subscribeToUtilisateurs() + gestion unsubscribe | F20: Frontend | G20: ETU0003525 | H20: 50 min | I20: Fait | J20: Haute
A21: 15 | B21: Firebase | C21: Web | D21: FirebaseSyncButton.tsx | E21: Composant React sync manuelle + bouton declenchement syncFull + affichage etat synchronisation + gestion erreurs | F21: Frontend | G21: ETU0003525 | H21: 35 min | I21: Fait | J21: Haute
A22: 16 | B22: Firebase | C22: Web | D22: initializeFirebaseUsers.ts | E22: Initialisation utilisateurs Firebase au demarrage + synchronisation comptes + gestion comptes par defaut | F22: Frontend | G22: ETU0003525 | H22: 30 min | I22: Fait | J22: Haute
A23: 17 | B23: Firebase | C23: Mobile | D23: firebase.ts (mobile) | E23: Init Firebase mobile cloud-mobile-c6ab2 + auth + Firestore + FCM messaging + requestNotificationPermission() + onMessageListener() | F23: Mobile | G23: ETU0003525 | H23: 50 min | I23: Fait | J23: Haute
A24: 18 | B24: Firebase | C24: Mobile | D24: firebaseSyncService.ts (Mobile) | E24: CRUD + subscriptions temps reel signalements/travaux/utilisateurs + gestion unsubscribe (adapte Ionic/Vue) | F24: Mobile | G24: ETU0003525 | H24: 1 h 15 min | I24: Fait | J24: Haute
A25: 19 | B25: Firebase | C25: Mobile | D25: firebaseNotificationService.ts | E25: Notifications push FCM: init service + gestion tokens + ecoute changements statuts signalements + foreground/background | F25: Mobile | G25: ETU0003525 | H25: 1 h | I25: Fait | J25: Haute
A26: 20 | B26: Firebase | C26: Mobile | D26: SyncStatusFirebase.vue | E26: Composant Vue indicateur connexion Firebase + statistiques sync + affichage erreurs + integration SyncStatusFirebase | F26: Mobile | G26: ETU0003525 | H26: 35 min | I26: Fait | J26: Haute

Sheet V4
A1: 🚀 V4 — Robustesse + Firebase Backend + Tests
A2: Version | B2: V4
A3: Date | B3: 10/02/2026
A4: Objectif | B4: Robustesse + auto-init SQL + tests
A6: Ligne | B6: Categorie | C6: Module | D6: Page/Service | E6: Description | F6: Type | G6: Qui | H6: Estimation | I6: Statut | J6: Priorite
A7: 1 | B7: Base | C7: Auto-init | D7: application-docker.properties | E7: Forcer execution auto script.sql au demarrage conteneur. | F7: Backend | G7: ETU0003525 | H7: 35 min | I7: Fait | J7: Haute
A8: 2 | B8: Base | C8: script.sql | D8: route/resources | E8: Rendre script idempotent (CREATE IF NOT EXISTS + INSERT guarded). | F8: Backend | G8: ETU0003525 | H8: 1 h 10 min | I8: Fait | J8: Haute
A9: 3 | B9: Base | C9: Seed | D9: script.sql | E9: Injecter donnees tests coherentes (lieux, signalements, travaux). | F9: Backend | G9: ETU0003525 | H9: 1 h | I9: Fait | J9: Haute
A10: 4 | B10: Web | C10: Robustesse | D10: Parsing | E10: Normaliser statuts et nombres pour coherence web/mobile. | F10: Frontend | G10: ETU0003525 | H10: 50 min | I10: Fait | J10: Haute
A11: 5 | B11: Backend | C11: Travaux | D11: /api/travaux/stats/delais | E11: Ajouter stats delais min/moy/max. | F11: Backend | G11: ETU0003525 | H11: 55 min | I11: Fait | J11: Haute
A12: 6 | B12: Security | C12: Auth | D12: Sessions | E12: Invalidation sessions lors de deblocage/operations critiques. | F12: Backend | G12: ETU0003525 | H12: 40 min | I12: Fait | J12: Haute
A13: 7 | B13: QA | C13: Tests | D13: Postman | E13: Verifier flux complet auth + signalement + travaux + sync. | F13: QA | G13: ETU0003525 | H13: 1 h | I13: Fait | J13: Haute
A14: 8 | B14: Doc | C14: Execution | D14: README | E14: Mettre guide lancement docker et builds. | F14: Doc | G14: ETU0003525 | H14: 45 min | I14: Fait | J14: Haute
A15: 🔥 Firebase — Intégration Backend Java/Spring Boot (18/02/2026)
A16: 10 | B16: Firebase | C16: Backend | D16: FirebaseInitializer.java | E16: Initialisation Firebase Admin SDK + chargement firebase-service-account.json + prevention double init + gestion erreurs | F16: Backend | G16: ETU0003525 | H16: 45 min | I16: Fait | J16: Haute
A17: 11 | B17: Firebase | C17: Backend | D17: FirebaseConfig.java | E17: Configuration Spring @Configuration + @PostConstruct + variable env FIREBASE_SERVICE_ACCOUNT + logging erreurs init | F17: Backend | G17: ETU0003525 | H17: 40 min | I17: Fait | J17: Haute
A18: 12 | B18: Firebase | C18: Backend | D18: FirebaseSyncService.java | E18: Sync signalements: syncSignalementToFirestore() + syncSignalementsToLocal() + deleteSignalementFromFirestore() | F18: Backend | G18: ETU0003525 | H18: 1 h | I18: Fait | J18: Haute
A19: 13 | B19: Firebase | C19: Backend | D19: FirebaseSyncService.java | E19: Sync travaux: syncTravauxToFirestore() + syncTravauxToLocal() | F19: Backend | G19: ETU0003525 | H19: 50 min | I19: Fait | J19: Haute
A20: 14 | B20: Firebase | C20: Backend | D20: FirebaseSyncService.java | E20: Sync historiques travaux: syncHistoriquesTravauxToFirestore() + syncHistoriquesTravauxToLocal() | F20: Backend | G20: ETU0003525 | H20: 40 min | I20: Fait | J20: Haute
A21: 15 | B21: Firebase | C21: Backend | D21: FirebaseSyncService.java | E21: Sync utilisateurs non-MANAGER + syncFull() + syncOnStartup() + isFirebaseConfigured() | F21: Backend | G21: ETU0003525 | H21: 1 h | I21: Fait | J21: Haute

Sheet V5
A1: 🚀 V5 —
A2: Version | B2: V5
A3: Date | B3: 15/02/2026
A4: Objectif | B4: Fonctionnalites pro analytics/audit/impact
A6: Ligne | B6: Categorie | C6: Module | D6: Page/Service | E6: Description | F6: Type | G6: Qui | H6: Estimation | I6: Statut | J6: Priorite
A7: 1 | B7: Pro | C7: Analytics | D7: /api/analytics/criticality | E7: Scoring criticite multi-facteurs pour prioriser interventions. | F7: Backend | G7: ETU0003525 | H7: 1 h 20 min | I7: Fait | J7: Critique
A8: 2 | B8: Pro | C8: Audit | D8: /api/analytics/audit | E8: Table audit_logs + journal actions create/update/delete/lock/unlock. | F8: Backend | G8: ETU0003525 | H8: 1 h 20 min | I8: Fait | J8: Critique
A9: 3 | B9: Pro | C9: Analytics | D9: /api/analytics/impact | E9: KPI impact: ouverts/clotures, budget/m2, delai moyen, hotspots. | F9: Backend | G9: ETU0003525 | H9: 1 h | I9: Fait | J9: Critique
A10: 4 | B10: Pro | C10: Web | D10: /analytics/criticality | E10: Page web Criticite dediee. | F10: Frontend | G10: ETU0003525 | H10: 50 min | I10: Fait | J10: Haute
A11: 5 | B11: Pro | C11: Web | D11: /analytics/audit | E11: Page web Audit Trail dediee. | F11: Frontend | G11: ETU0003525 | H11: 45 min | I11: Fait | J11: Haute
A12: 6 | B12: Pro | C12: Web | D12: /analytics/impact | E12: Page web Impact & performance dediee. | F12: Frontend | G12: ETU0003525 | H12: 45 min | I12: Fait | J12: Haute
A13: 7 | B13: Pro | C13: Web | D13: Widget | E13: Mini carte scrollable utilisateurs bloques en bas droite. | F13: Frontend | G13: ETU0003525 | H13: 35 min | I13: Fait | J13: Haute
A14: 8 | B14: Pro | C14: Mobile | D14: Tab2 | E14: 3 contenus mobiles synchronises: Criticite, Audit, Impact. | F14: Mobile | G14: ETU0003525 | H14: 1 h 30 min | I14: Fait | J14: Critique
A15: 9 | B15: Pro | C15: Base | D15: script.sql | E15: Seed utilisateur bloque + jeux de donnees analytics. | F15: Backend | G15: ETU0003525 | H15: 40 min | I15: Fait | J15: Haute
A16: 10 | B16: Pro | C16: Verification | D16: Builds | E16: Valider compilation Maven + build web + build mobile. | F16: QA | G16: ETU0003525 | H16: 30 min | I16: Fait | J16: Haute
A17: 11 | B17: Pro | C17: Analytics | D17: /analytics | E17: Corriger page /analytics/audit vide: initialisation automatique du journal (seed SQL + fallback backend). | F17: Backend | G17: ETU0003525 | H17: 35 min | I17: Fait | J17: Critique
A18: 12 | B18: Pro | C18: Analytics | D18: /analytics | E18: Ajouter nouvelle page /analytics/charts avec graphiques globaux (statuts, types, criticite) et navigation. | F18: Frontend | G18: ETU0003525 | H18: 1 h 15 min | I18: Fait | J18: Haute

Sheet stats_globales
A1: 📈 STATISTIQUES GLOBALES — Cloud S5 RouteWatch | ETU0003525
A2: 📊 Statistiques par version | H2: ✅ Répartition Statuts
A3: Version | B3: Nb tâches | C3: Estimation (h) | D3: Temps passé (h) | E3: Avancement moy. | F3: Date livraison | H3: Statut | I3: Nombre
A4: V1 | B4: =COUNTIF('liste des taches'!B:B,"V1") -> 15 | C4: =SUMIFS('liste des taches'!J:J,'liste des taches'!B:B,"V1") -> 12.66 | D4: =SUMIFS('liste des taches'!K:K,'liste des taches'!B:B,"V1") -> 14.18 | E4: =IF(C4=0,0,D4/C4) -> 1.1200632 | F4: 13/01/2026 | H4: Fait | I4: =COUNTIF('liste des taches'!N:N,"Fait") -> 75
A5: V2 | B5: =COUNTIF('liste des taches'!B:B,"V2") -> 15 | C5: =SUMIFS('liste des taches'!J:J,'liste des taches'!B:B,"V2") -> 19.42 | D5: =SUMIFS('liste des taches'!K:K,'liste des taches'!B:B,"V2") -> 19.42 | E5: =IF(C5=0,0,D5/C5) -> 1 | F5: 20/01/2026 | H5: En cours | I5: =COUNTIF('liste des taches'!N:N,"En cours") -> 0
A6: V3 | B6: =COUNTIF('liste des taches'!B:B,"V3") -> 19 | C6: =SUMIFS('liste des taches'!J:J,'liste des taches'!B:B,"V3") -> 21.98 | D6: =SUMIFS('liste des taches'!K:K,'liste des taches'!B:B,"V3") -> 26.48 | E6: =IF(C6=0,0,D6/C6) -> 1.2047316 | F6: 03/02/2026 | H6: A faire | I6: =COUNTIF('liste des taches'!N:N,"A faire") -> 0
A7: V4 | B7: =COUNTIF('liste des taches'!B:B,"V4") -> 14 | C7: =SUMIFS('liste des taches'!J:J,'liste des taches'!B:B,"V4") -> 11.84 | D7: =SUMIFS('liste des taches'!K:K,'liste des taches'!B:B,"V4") -> 17.17 | E7: =IF(C7=0,0,D7/C7) -> 1.4501689 | F7: 10/02/2026
A8: V5 | B8: =COUNTIF('liste des taches'!B:B,"V5") -> 12 | C8: =SUMIFS('liste des taches'!J:J,'liste des taches'!B:B,"V5") -> 14.07 | D8: =SUMIFS('liste des taches'!K:K,'liste des taches'!B:B,"V5") -> 16.12 | E8: =IF(C8=0,0,D8/C8) -> 1.1457001 | F8: 15/02/2026 | H8: 🔧 Répartition par Type
A9: TOTAL | B9: =SUM(B4:B8) -> 75 | C9: =SUM(C4:C8) -> 79.97 | D9: =SUM(D4:D8) -> 93.37 | E9: =IF(C9=0,0,D9/C9) -> 1.1675628 | H9: Type | I9: Nombre
H10: Backend | I10: =COUNTIF('liste des taches'!G:G,"Backend") -> 32
A11: 🎯 KPI Globaux | H11: Frontend | I11: =COUNTIF('liste des taches'!G:G,"Frontend") -> 24
A12: Total tâches | B12: =COUNTIF('liste des taches'!B:B,"V1")+COUNTIF('liste des taches'!B:B,"V2")+COUNTIF('liste des taches'!B:B,"V3")+COUNTIF('liste des taches'!B:B,"V4")+COUNTIF('liste des taches'!B:B,"V5") -> 75 | H12: Mobile | I12: =COUNTIF('liste des taches'!G:G,"Mobile") -> 13
A13: Estimation totale (h) | B13: =SUM('liste des taches'!J:J) -> 79.97 | H13: DevOps | I13: =COUNTIF('liste des taches'!G:G,"DevOps") -> 1
A14: Temps passé total (h) | B14: =SUM('liste des taches'!K:K) -> 93.37 | H14: QA | I14: =COUNTIF('liste des taches'!G:G,"QA") -> 2
A15: Avancement global | B15: =IF(B13=0,0,B14/B13) -> 1.1675628 | H15: Doc | I15: =COUNTIF('liste des taches'!G:G,"Doc") -> 1
A16: Tâches terminées | B16: =COUNTIF('liste des taches'!N:N,"Fait") -> 75
A17: Tâches en cours | B17: =COUNTIF('liste des taches'!N:N,"En cours") -> 0
